Workbook

Sheet Blad2
B2: CHECKLIST ROBOTICA PROJECT
B3: STUDENT1 | C3: Robbie Vandeputte
B4: STUDENT2 | C4: Yassin Kasmi
B5: STUDENT3 | C5: Bullen Daan
B6: PROJECT | C6: GEDAAN | D6: DOCUMENTATIE
B7: MIN requirements | C7: =SUM(COUNTIF(Checklist_RobotProject!C2:C27,TRUE))/26 -> 0.76923077 | D7: =SUM(COUNTIF(Checklist_RobotProject!D2:D27,TRUE))/26 -> 0.76923077
B8: ADD and EXRA requirements | C8: =COUNTIF(Checklist_RobotProject!C28:C65,TRUE) -> 4 | D8: =COUNTIF(Checklist_RobotProject!D28:D65,TRUE) -> 4
B9: SKILS | C9: GEDAAN | D9: DOCUMENTATIE
B10: =C3 -> Robbie Vandeputte | C10: =SUM(COUNTIF(Skills_Robbie!C3:C23,TRUE))/21 -> 0.80952381 | D10: =SUM(COUNTIF(Skills_Robbie!D3:D23,TRUE))/21 -> 0.57142857
B11: =C4 -> Yassin Kasmi | C11: =SUM(COUNTIF(Skills_Yassin!C3:C23,TRUE))/21 -> 0 | D11: =SUM(COUNTIF(Skills_Yassin!D3:D23,TRUE))/21 -> 0
B12: =C5 -> Bullen Daan | C12: =SUM(COUNTIF(Skills_Daan!C3:C23,TRUE))/21 -> 0 | D12: =SUM(COUNTIF(Skills_Daan!D3:D23,TRUE))/21 -> 0

Sheet Checklist_RobotProject
B1: Requirement | C1: IN project | D1: Gedocumenteerd
A2: MIN | B2: 1* Main project met een fysieke robot | C2: TRUE | D2: TRUE | E2: =C2+D2 -> 2
A3: MIN | B3: Minimaal 20 bewegingen die de capaciteit van de robot tonen | C3: TRUE | D3: TRUE | E3: =C3+D3 -> 2 | P3: 0
A4: MIN | B4: Combinatie van rechtlijnige en joint/ptp bewegingen | C4: TRUE | D4: TRUE | E4: =C4+D4 -> 2 | P4: 1
A5: MIN | B5: Cnt en fine bewegingen | C5: FALSE | D5: FALSE | E5: documenteren, kunnen uitleggen | P5: 2
A6: MIN | B6: Correcte bewegingsinstructies (snelheid/versnelling/tool/base) | C6: TRUE | D6: TRUE | E6: =C6+D6 -> 2 | P6: 3
A7: MIN | B7: Wait instructie - TIME | C7: TRUE | D7: TRUE | E7: =C7+D7 -> 2 | P7: 4
A8: MIN | B8: Wait instructie - I/O | C8: TRUE | D8: TRUE | E8: =C8+D8 -> 2 | P8: 5
A9: MIN | B9: Correcte aansturing van de grijper via een zelfgemaakt (onder)programma. | C9: FALSE | D9: FALSE | E9: nog eens bekijken | P9: 6
A10: MIN | B10: Gebruik van meerdere deelprogramma’s (met en zonder bewegingen). | C10: TRUE | D10: TRUE | E10: =C10+D10 -> 2 | P10: 7
A11: MIN | B11: Minimaal 1 TCP + Payload + kalibratie | C11: TRUE | D11: TRUE | E11: =C11+D11 -> 2 | P11: 8
A12: MIN | B12: Minimaal 1 Base/frame + kalibratie | C12: TRUE | D12: TRUE | E12: =C12+D12 -> 2 | P12: 9
A13: MIN | B13: Minimaal één interrupt-afhandeling | C13: TRUE | D13: TRUE | E13: =C13+D13 -> 2 | P13: 10
A14: MIN | B14: Correct gebruik van een homepositie | C14: TRUE | D14: TRUE | E14: =C14+D14 -> 2
A15: MIN | B15: Back-up | C15: FALSE | D15: FALSE | E15: nog eens bekijken
A16: MIN | B16: Correct gebruik van commentaar | C16: TRUE | D16: TRUE | E16: =C16+D16 -> 2
A17: MIN | B17: Principewerking van een “zonebewaking” | C17: FALSE | D17: FALSE | E17: documenteren, zeker principe van handshake
A18: MIN | B18: Cyclustijd meting | C18: FALSE | D18: FALSE | E18: =C18+D18 -> 0
A19: MIN | B19: Gebruik van lokale data of variabelen | C19: TRUE | D19: TRUE | E19: =C19+D19 -> 2
A20: MIN | B20: Gebruik van globale data of variabelen | C20: TRUE | D20: TRUE
A21: MIN | B21: Gebruik van input en output | C21: TRUE | D21: TRUE | E21: =C21+D21 -> 2
A22: MIN | B22: Gebruik van loops (programma afloop) | C22: TRUE | D22: TRUE | E22: =C22+D22 -> 2
A23: MIN | B23: Asbeveiliging (en/of andere beveiligingen) | C23: FALSE | D23: FALSE | E23: nog eens bekijken
A24: MIN | B24: SPS programmatie (KUKA) / conditie (Fanuc) | C24: TRUE | D24: TRUE | E24: =C24+D24 -> 2
A25: MIN | B25: Meerdere berekenden punten (of baseverschuiving/offset) | C25: TRUE | D25: TRUE | E25: =C25+D25 -> 2
A26: MIN | B26: Het gebruik van een Array (KUKA) | C26: TRUE | D26: TRUE | E26: =C26+D26 -> 2
A27: MIN | B27: De snelheid van de bewegingen is variabel instelbaar via 3 voorgeprogrammeerde parameters: Fast; medium; slow | C27: TRUE | D27: TRUE | E27: =C27+D27 -> 2
A28: ADD | B28: Rapportering ++ (=”professionele rapportering”) | C28: TRUE | D28: TRUE | E28: =C28+D28 -> 2
A29: ADD | B29: Robot start met een hoofdprogramma en werk een afloop af aan de hand van programmanummers/jobs. | C29: FALSE | D29: FALSE | E29: =C29+D29 -> 0
A30: ADD | B30: Verschillende types van uitvoeringen (voorbeeld variaties van op te nemen delen). | C30: FALSE | D30: FALSE | E30: =C30+D30 -> 0
A31: ADD | B31: Correcte foutafhandeling van de grijper. (De robot zal nooit in de fout gaan, zelfs als er delen verwijderd worden uit de cel.) | C31: FALSE | D31: FALSE | E31: =C31+D31 -> 0
A32: ADD | B32: Correcte deelcontrole en afhandeling van de grijper | C32: FALSE | D32: FALSE | E32: =C32+D32 -> 0
A33: ADD | B33: Cyclus optimalisatie ++ | C33: FALSE | D33: FALSE | E33: =C33+D33 -> 0
A34: ADD | B34: Loggegevens (Timing, program counter, error …) | C34: FALSE | D34: FALSE | E34: =C34+D34 -> 0
A35: ADD | B35: Grijperwissel | C35: FALSE | D35: FALSE | E35: =C35+D35 -> 0
... A44: ADD | B44: Aansluiten van drukknoppen om I/O te laten werken (drukknoppen + verlichting) na demontage voor bachelorproef | C44: TRUE | D44: TRUE | E44: =C44+D44 -> 2
A45: ADD | C45: FALSE | D45: FALSE | E45: =C45+D45 -> 0
A46: ADD | C46: FALSE | D46: FALSE | E46: =C46+D46 -> 0
A47: ADD | B47: … | C47: FALSE | D47: FALSE | E47: =C47+D47 -> 0
A48: ADD | B48: … | C48: FALSE | D48: FALSE | E48: =C48+D48 -> 0
...

Sheet Skills_Robbie
B1: NAAM STUDENT: Robbie Vandeputte
B2: Requirement | C2: IN project | D2: Gedocumenteerd
A3: MIN | B3: Installatie opstarten + foutmeldingen interpreteren | C3: TRUE | D3: FALSE | E3: =C3+D3 -> 1
A4: MIN | B4: Handbediening van de robot | C4: TRUE | D4: TRUE | E4: =C4+D4 -> 2 | P4: 0
A5: MIN | B5: Robotprogramma testen in manuele mode (T1) | C5: TRUE | D5: TRUE | E5: =C5+D5 -> 2 | P5: 1
A6: MIN | B6: Robotprogramma testen in snelle mode (T2) → Opgelet SAFETY!!! | C6: TRUE | D6: FALSE | E6: =C6+D6 -> 1 | P6: 2
A7: MIN | B7: Robotprogramma testen in automatische mode | C7: TRUE | D7: FALSE | E7: =C7+D7 -> 1 | P7: 3
A8: MIN | B8: Cyclustijd meting en optimalisatie | C8: FALSE | D8: FALSE | E8: =C8+D8 -> 0 | P8: 4
A9: MIN | B9: Rapportering: | C9: TRUE | D9: TRUE | E9: =C9+D9 -> 2 | P9: 5
A10: MIN | B10: Documentatie | C10: TRUE | D10: TRUE | E10: =C10+D10 -> 2 | P10: 6
A11: MIN | B11: Back-up | C11: TRUE | D11: TRUE | E11: =C11+D11 -> 2 | P11: 7
A12: MIN | B12: Omschrijving | C12: TRUE | D12: TRUE | E12: =C12+D12 -> 2 | P12: 8
A13: MIN | B13: Aanmaken van een robotsimulatie | C13: FALSE | D13: FALSE | E13: =C13+D13 -> 0 | P13: 9
A14: MIN | B14: Interpreteren van een simulatie | C14: FALSE | D14: FALSE | E14: =C14+D14 -> 0 | P14: 10
A15: MIN | B15: De robot in een productielijn & communicatie PLC & periferie. | C15: TRUE | D15: FALSE | E15: =C15+D15 -> 1
A16: MIN | B16: Basiskennis van de fysieke robot | C16: TRUE | D16: TRUE | E16: =C16+D16 -> 2
A17: MIN | B17: Basiskennis van de simulatieomgeving | C17: FALSE | D17: FALSE | E17: =C17+D17 -> 0
A18: MIN | B18: (Her)teachen van punten, en weten wanneer dit nodig is | C18: TRUE | D18: TRUE | E18: =C18+D18 -> 2
A19: MIN | B19: Het nut van een TCP, payload en base/frame kennen, en kunnen toepassen | C19: TRUE | D19: TRUE | E19: =C19+D19 -> 2
A20: MIN | B20: Het maken van een back-up | C20: TRUE | D20: TRUE | E20: =C20+D20 -> 2
A21: MIN | B21: Instellen van nodige saftey voor zowel operator als robot | C21: TRUE | D21: FALSE | E21: =C21+D21 -> 1
A22: MIN | B22: Het gebruiken van variabele (lokaal en globaal) | C22: TRUE | D22: TRUE | E22: =C22+D22 -> 2
A23: MIN | B23: Het kunnen interpreteren van een punt-coördinaat en de data ervan | C23: TRUE | D23: TRUE | E23: =C23+D23 -> 2

Sheet Skills_Yassin
B1: NAAM STUDENT:
B2: Requirement | C2: IN project | D2: Gedocumenteerd
A3: MIN | B3: Installatie opstarten + foutmeldingen interpreteren | C3: FALSE | D3: FALSE | E3: =C3+D3 -> 0
A4: MIN | B4: Handbediening van de robot | C4: FALSE | D4: FALSE | E4: =C4+D4 -> 0 | P4: 0
A5: MIN | B5: Robotprogramma testen in manuele mode (T1) | C5: FALSE | D5: FALSE | E5: =C5+D5 -> 0 | P5: 1
A6: MIN | B6: Robotprogramma testen in snelle mode (T2) → Opgelet SAFETY!!! | C6: FALSE | D6: FALSE | E6: =C6+D6 -> 0 | P6: 2
A7: MIN | B7: Robotprogramma testen in automatische mode | C7: FALSE | D7: FALSE | E7: =C7+D7 -> 0 | P7: 3
A8: MIN | B8: Cyclustijd meting en optimalisatie | C8: FALSE | D8: FALSE | E8: =C8+D8 -> 0 | P8: 4
A9: MIN | B9: Rapportering: | C9: FALSE | D9: FALSE | E9: =C9+D9 -> 0 | P9: 5
A10: MIN | B10: Documentatie | C10: FALSE | D10: FALSE | E10: =C10+D10 -> 0 | P10: 6
A11: MIN | B11: Back-up | C11: FALSE | D11: FALSE | E11: =C11+D11 -> 0 | P11: 7
A12: MIN | B12: Omschrijving | C12: FALSE | D12: FALSE | E12: =C12+D12 -> 0 | P12: 8
A13: MIN | B13: Aanmaken van een robotsimulatie | C13: FALSE | D13: FALSE | E13: =C13+D13 -> 0 | P13: 9
A14: MIN | B14: Interpreteren van een simulatie | C14: FALSE | D14: FALSE | E14: =C14+D14 -> 0 | P14: 10
A15: MIN | B15: De robot in een productielijn & communicatie PLC & periferie. | C15: FALSE | D15: FALSE | E15: =C15+D15 -> 0
A16: MIN | B16: Basiskennis van de fysieke robot | C16: FALSE | D16: FALSE | E16: =C16+D16 -> 0
A17: MIN | B17: Basiskennis van de simulatieomgeving | C17: FALSE | D17: FALSE | E17: =C17+D17 -> 0
A18: MIN | B18: (Her)teachen van punten, en weten wanneer dit nodig is | C18: FALSE | D18: FALSE | E18: =C18+D18 -> 0
A19: MIN | B19: Het nut van een TCP, payload en base/frame kennen, en kunnen toepassen | C19: FALSE | D19: FALSE | E19: =C19+D19 -> 0
A20: MIN | B20: Het maken van een back-up | C20: FALSE | D20: FALSE | E20: =C20+D20 -> 0
A21: MIN | B21: Instellen van nodige saftey voor zowel operator als robot | C21: FALSE | D21: FALSE | E21: =C21+D21 -> 0
A22: MIN | B22: Het gebruiken van variabele (lokaal en globaal) | C22: FALSE | D22: FALSE | E22: =C22+D22 -> 0
A23: MIN | B23: Het kunnen interpreteren van een punt-coördinaat en de data ervan | C23: FALSE | D23: FALSE | E23: =C23+D23 -> 0

Sheet Skills_Daan
B1: NAAM STUDENT:
B2: Requirement | C2: IN project | D2: Gedocumenteerd
A3: MIN | B3: Installatie opstarten + foutmeldingen interpreteren | C3: FALSE | D3: FALSE | E3: =C3+D3 -> 0
A4: MIN | B4: Handbediening van de robot | C4: FALSE | D4: FALSE | E4: =C4+D4 -> 0 | P4: 0
A5: MIN | B5: Robotprogramma testen in manuele mode (T1) | C5: FALSE | D5: FALSE | E5: =C5+D5 -> 0 | P5: 1
A6: MIN | B6: Robotprogramma testen in snelle mode (T2) → Opgelet SAFETY!!! | C6: FALSE | D6: FALSE | E6: =C6+D6 -> 0 | P6: 2
A7: MIN | B7: Robotprogramma testen in automatische mode | C7: FALSE | D7: FALSE | E7: =C7+D7 -> 0 | P7: 3
A8: MIN | B8: Cyclustijd meting en optimalisatie | C8: FALSE | D8: FALSE | E8: =C8+D8 -> 0 | P8: 4
A9: MIN | B9: Rapportering: | C9: FALSE | D9: FALSE | E9: =C9+D9 -> 0 | P9: 5
A10: MIN | B10: Documentatie | C10: FALSE | D10: FALSE | E10: =C10+D10 -> 0 | P10: 6
A11: MIN | B11: Back-up | C11: FALSE | D11: FALSE | E11: =C11+D11 -> 0 | P11: 7
A12: MIN | B12: Omschrijving | C12: FALSE | D12: FALSE | E12: =C12+D12 -> 0 | P12: 8
A13: MIN | B13: Aanmaken van een robotsimulatie | C13: FALSE | D13: FALSE | E13: =C13+D13 -> 0 | P13: 9
A14: MIN | B14: Interpreteren van een simulatie | C14: FALSE | D14: FALSE | E14: =C14+D14 -> 0 | P14: 10
A15: MIN | B15: De robot in een productielijn & communicatie PLC & periferie. | C15: FALSE | D15: FALSE | E15: =C15+D15 -> 0
A16: MIN | B16: Basiskennis van de fysieke robot | C16: FALSE | D16: FALSE | E16: =C16+D16 -> 0
A17: MIN | B17: Basiskennis van de simulatieomgeving | C17: FALSE | D17: FALSE | E17: =C17+D17 -> 0
A18: MIN | B18: (Her)teachen van punten, en weten wanneer dit nodig is | C18: FALSE | D18: FALSE | E18: =C18+D18 -> 0
A19: MIN | B19: Het nut van een TCP, payload en base/frame kennen, en kunnen toepassen | C19: FALSE | D19: FALSE | E19: =C19+D19 -> 0
A20: MIN | B20: Het maken van een back-up | C20: FALSE | D20: FALSE | E20: =C20+D20 -> 0
A21: MIN | B21: Instellen van nodige saftey voor zowel operator als robot | C21: FALSE | D21: FALSE | E21: =C21+D21 -> 0
A22: MIN | B22: Het gebruiken van variabele (lokaal en globaal) | C22: FALSE | D22: FALSE | E22: =C22+D22 -> 0
A23: MIN | B23: Het kunnen interpreteren van een punt-coördinaat en de data ervan | C23: FALSE | D23: FALSE | E23: =C23+D23 -> 0
